[2023-03-14T21:36:52.921+0000] {taskinstance.py:1083} INFO - Dependencies all met for <TaskInstance: validacao_pu_v2.consultar_pu_galaxia manual__2023-03-14T21:26:48.597652+00:00 [queued]>
[2023-03-14T21:36:52.930+0000] {taskinstance.py:1083} INFO - Dependencies all met for <TaskInstance: validacao_pu_v2.consultar_pu_galaxia manual__2023-03-14T21:26:48.597652+00:00 [queued]>
[2023-03-14T21:36:52.930+0000] {taskinstance.py:1279} INFO - 
--------------------------------------------------------------------------------
[2023-03-14T21:36:52.930+0000] {taskinstance.py:1280} INFO - Starting attempt 3 of 6
[2023-03-14T21:36:52.930+0000] {taskinstance.py:1281} INFO - 
--------------------------------------------------------------------------------
[2023-03-14T21:36:52.944+0000] {taskinstance.py:1300} INFO - Executing <Task(_PythonDecoratedOperator): consultar_pu_galaxia> on 2023-03-14 21:26:48.597652+00:00
[2023-03-14T21:36:53.001+0000] {standard_task_runner.py:55} INFO - Started process 28262 to run task
[2023-03-14T21:36:53.007+0000] {standard_task_runner.py:82} INFO - Running: ['***', 'tasks', 'run', 'validacao_pu_v2', 'consultar_pu_galaxia', 'manual__2023-03-14T21:26:48.597652+00:00', '--job-id', '421', '--raw', '--subdir', 'DAGS_FOLDER/examples/validacao_pu_v2.py', '--cfg-path', '/tmp/tmpodv_rre2']
[2023-03-14T21:36:53.008+0000] {standard_task_runner.py:83} INFO - Job 421: Subtask consultar_pu_galaxia
[2023-03-14T21:36:53.068+0000] {task_command.py:388} INFO - Running <TaskInstance: validacao_pu_v2.consultar_pu_galaxia manual__2023-03-14T21:26:48.597652+00:00 [running]> on host 40565fc59ef6
[2023-03-14T21:36:53.137+0000] {taskinstance.py:1509} INFO - Exporting the following env vars:
AIRFLOW_CTX_DAG_OWNER=alexandre.yoshimatsu
AIRFLOW_CTX_DAG_ID=validacao_pu_v2
AIRFLOW_CTX_TASK_ID=consultar_pu_galaxia
AIRFLOW_CTX_EXECUTION_DATE=2023-03-14T21:26:48.597652+00:00
AIRFLOW_CTX_TRY_NUMBER=3
AIRFLOW_CTX_DAG_RUN_ID=manual__2023-03-14T21:26:48.597652+00:00
[2023-03-14T21:36:53.147+0000] {taskinstance.py:1768} ERROR - Task failed with exception
Traceback (most recent call last):
  File "/home/airflow/.local/lib/python3.7/site-packages/airflow/decorators/base.py", line 217, in execute
    return_value = super().execute(context)
  File "/home/airflow/.local/lib/python3.7/site-packages/airflow/operators/python.py", line 175, in execute
    return_value = self.execute_callable()
  File "/home/airflow/.local/lib/python3.7/site-packages/airflow/operators/python.py", line 192, in execute_callable
    return self.python_callable(*self.op_args, **self.op_kwargs)
  File "/opt/airflow/dags/examples/validacao_pu_v2.py", line 93, in consultar_pu_galaxia
    operacoes_dia = kwargs["ti"].xcom_pull(key="operacoes_dia")
  File "/home/airflow/.local/lib/python3.7/site-packages/airflow/utils/session.py", line 75, in wrapper
    return func(*args, session=session, **kwargs)
  File "/home/airflow/.local/lib/python3.7/site-packages/airflow/models/taskinstance.py", line 2367, in xcom_pull
    return XCom.deserialize_value(first)
  File "/home/airflow/.local/lib/python3.7/site-packages/airflow/models/xcom.py", line 661, in deserialize_value
    return BaseXCom._deserialize_value(result, False)
  File "/home/airflow/.local/lib/python3.7/site-packages/airflow/models/xcom.py", line 654, in _deserialize_value
    return json.loads(result.value.decode("UTF-8"), cls=XComDecoder, object_hook=object_hook)
  File "/usr/local/lib/python3.7/json/__init__.py", line 361, in loads
    return cls(**kw).decode(s)
  File "/usr/local/lib/python3.7/json/decoder.py", line 337, in decode
    obj, end = self.raw_decode(s, idx=_w(s, 0).end())
  File "/usr/local/lib/python3.7/json/decoder.py", line 353, in raw_decode
    obj, end = self.scan_once(s, idx)
  File "/home/airflow/.local/lib/python3.7/site-packages/airflow/utils/json.py", line 215, in object_hook
    raise ImportError(f"{classname} was not found in allow list for import")
ImportError: unusual_prefix_0d7ab9324b505a66d0bdfa12c43229845d5e3073_validacao_pu_v2.Operacao was not found in allow list for import
[2023-03-14T21:36:53.155+0000] {taskinstance.py:1323} INFO - Marking task as UP_FOR_RETRY. dag_id=validacao_pu_v2, task_id=consultar_pu_galaxia, execution_date=20230314T212648, start_date=20230314T213652, end_date=20230314T213653
[2023-03-14T21:36:53.166+0000] {standard_task_runner.py:105} ERROR - Failed to execute job 421 for task consultar_pu_galaxia (unusual_prefix_0d7ab9324b505a66d0bdfa12c43229845d5e3073_validacao_pu_v2.Operacao was not found in allow list for import; 28262)
[2023-03-14T21:36:53.178+0000] {local_task_job.py:208} INFO - Task exited with return code 1
[2023-03-14T21:36:53.200+0000] {taskinstance.py:2578} INFO - 0 downstream tasks scheduled from follow-on schedule check
